Workbook

Sheet Code Options
A1: RN | B1: Material_Type | C1: Retro_Proactive | D1: Rev_1 | E1: Rev_2 | F1: Spatial_Scale | G1: Bio_Obj | H1: Concepts_Mentioned | I1: Doc_Type | J1: Physical_Obj | K1: Social_Econ_Obj | L1: Target_SH | M1: AR_Def | N1: LT_End | O1: Notes | P1: Spec_Obj | Q1: Spec_Spatial_scale | R1: Whats_monitored
A2: 1 | B2: Composite | C2: Retro | D2: Will | E2: Will | F2: County/Local | G2: Habitat | H2: Fish.Enhancement | I2: State_Code | J2: Hab_enhancement | K2: Rec_Fish | L2: AR_proj_plan_mngrs
A3: 2 | B3: Concrete | C3: Pro | D3: Cyndi | E3: Cyndi | F3: State | G3: Production | H3: Comm.Fish.Mngmt | I3: Fed_Code | J3: Disposal | K3: Comm_Fish | L3: AS_constructors
A4: 3 | B4: Metal | C4: Unsure | D4: Jon | E4: Nick | F4: Regional | G4: Aggregation | H4: Rec.Fish.Mngmt | I4: State_Plan | J4: Mitig. | K4: Chart_Fish | L4: Permit_reg_agencies
A5: 4 | B5: Other | D5: LM | F5: National | G5: Biodiversity | H5: Creation of AR Mat | I5: Summ_Article | J5: Hab_restoration | K5: Non-Fish_rec | L5: people_interested
A6: 5 | B6: Rock | D6: Nick | H6: Siting and Deployment Regs | I6: Guide | J6: Wave_attenuation | K6: Scuba | L6: anglers
A7: 6 | B7: Tires/Rubber

Sheet States and Locations
A1: State_Num | B1: State | C1: Lat | D1: Lon
A2: 1 | B2: Maine | C2: 45.3667 | D2: -69.2333
A3: 2 | B3: New Hampshire | C3: 43.6833 | D3: -71.5833
A4: 3 | B4: Massachussetts | C4: 42.4 | D4: -71.3833
A5: 4 | B5: Rhode Island | C5: 41.6667 | D5: -71.5
A6: 5 | B6: Connecticut | C6: 41.6 | D6: -72.7
A7: 6 | B7: New York | C7: 42.9667 | D7: -75.5167
A8: 7 | B8: New Jersey | C8: 39.8333 | D8: -74.8667
A9: 8 | B9: Delaware | C9: 38.9833 | D9: -75.5167
A10: 9 | B10: Maryland | C10: 39.05 | D10: -76.6333
A11: 10 | B11: Virginia | C11: 37.5167 | D11: -78.6333
A12: 11 | B12: North Carolina | C12: 35.7833 | D12: -79.8167
A13: 12 | B13: South Carolina | C13: 33.8333 | D13: -81.1667
... A26: 999 | B26: UNK | C26: 25 | D26: -90

Sheet Master Sheet
B1: Material_Type | D1: Retro_Proactive | F1: Rev_1 | H1: Rev_2 | J1: Spatial_Scale | L1: Bio_Obj | N1: Concepts_Mentioned | P1: Doc_Type | Q1: State_ifapp | R1: State | S1: Lat | T1: Lon | V1: Physical_Obj | X1: Social_Econ_Obj | Z1: Target_SH | AB1: AR_Def | AC1: LT_End | AD1: Notes | AE1: Spec_Obj | AF1: Spec_Spatial_scale | AG1: Whats_monitored
A2: =RANDBETWEEN(1,6) -> 1 | B2: =VLOOKUP('Master Sheet'!A2,'Code Options'!$A$1:$B$7,2) -> Composite | C2: =RANDBETWEEN(1,3) -> 3 | D2: =VLOOKUP('Master Sheet'!C2,'Code Options'!$A$1:$R$7,3) -> Unsure | E2: =RANDBETWEEN(1,5) -> 4 | F2: =VLOOKUP('Master Sheet'!E2,'Code Options'!$A$1:$R$7,4) -> LM | G2: =RANDBETWEEN(1,3) -> 3 | H2: =VLOOKUP('Master Sheet'!E2,'Code Options'!$A$1:$R$7,5) -> 0 | I2: =RANDBETWEEN(1,4) -> 1 | J2: =VLOOKUP('Master Sheet'!G2,'Code Options'!$A$1:$R$7,6) -> Regional | K2: =RANDBETWEEN(1,4) -> 1 | L2: =VLOOKUP('Master Sheet'!I2,'Code Options'!$A$1:$R$7,7) -> Habitat | M2: =RANDBETWEEN(1,5) -> 1 | N2: =VLOOKUP('Master Sheet'!K2,'Code Options'!$A$1:$R$7,8) -> Fish.Enhancement | O2: =RANDBETWEEN(1,5) -> 5 | P2: =VLOOKUP('Master Sheet'!E2,'Code Options'!$A$1:$R$7,9) -> Summ_Article | Q2: {=_xlfn.IFS(P2 ="State_Plan", RANDBETWEEN(1,23), P2 ="State_Code", RANDBETWEEN(1,23), P2 = "Fed_Code", 99, P2 = "Summ_Article", 999, P2 = "Guide", 999)} -> 999 | R2: =VLOOKUP(Q2,'States and Locations'!$A$1:$B$26,2) -> UNK | S2: =VLOOKUP(Q2,'States and Locations'!$A$1:$D$26,3) -> 25 | T2: =VLOOKUP(Q2,'States and Locations'!$A$1:$D$26,4) -> -90 | U2: =RANDBETWEEN(1,5) -> 2 | V2: =VLOOKUP('Master Sheet'!E2,'Code Options'!$A$1:$R$7,10) -> Hab_restoration | W2: =RANDBETWEEN(1,5) -> 4 | X2: =VLOOKUP('Master Sheet'!E2,'Code Options'!$A$1:$R$7,11) -> Non-Fish_rec | Y2: =RANDBETWEEN(1,5) -> 2 | Z2: =VLOOKUP('Master Sheet'!E2,'Code Options'!$A$1:$R$7,12) -> people_interested
A3: =RANDBETWEEN(1,6) -> 3 | B3: =VLOOKUP('Master Sheet'!A3,'Code Options'!$A$1:$B$7,2) -> Metal | C3: =RANDBETWEEN(1,3) -> 2 | D3: =VLOOKUP('Master Sheet'!C3,'Code Options'!$A$1:$R$7,3) -> Pro | E3: =RANDBETWEEN(1,5) -> 1 | F3: =VLOOKUP('Master Sheet'!E3,'Code Options'!$A$1:$R$7,4) -> Will | G3: =RANDBETWEEN(1,3) -> 2 | H3: =VLOOKUP('Master Sheet'!E3,'Code Options'!$A$1:$R$7,5) -> Will | I3: =RANDBETWEEN(1,4) -> 3 | J3: =VLOOKUP('Master Sheet'!G3,'Code Options'!$A$1:$R$7,6) -> State | K3: =RANDBETWEEN(1,4) -> 4 | L3: =VLOOKUP('Master Sheet'!I3,'Code Options'!$A$1:$R$7,7) -> Aggregation | M3: =RANDBETWEEN(1,5) -> 1 | N3: =VLOOKUP('Master Sheet'!K3,'Code Options'!$A$1:$R$7,8) -> Creation of AR Mat | O3: =RANDBETWEEN(1,5) -> 5 | P3: =VLOOKUP('Master Sheet'!E3,'Code Options'!$A$1:$R$7,9) -> State_Code | Q3: {=_xlfn.IFS(P3 ="State_Plan", RANDBETWEEN(1,23), P3 ="State_Code", RANDBETWEEN(1,23), P3 = "Fed_Code", 99, P3 = "Summ_Article", 999, P3 = "Guide", 999)} -> 20 | R3: =VLOOKUP(Q3,'States and Locations'!$A$1:$B$26,2) -> Oregon | S3: =VLOOKUP(Q3,'States and Locations'!$A$1:$D$26,3) -> 43.9333 | T3: =VLOOKUP(Q3,'States and Locations'!$A$1:$D$26,4) -> -120.5667 | U3: =RANDBETWEEN(1,5) -> 3 | V3: =VLOOKUP('Master Sheet'!E3,'Code Options'!$A$1:$R$7,10) -> Hab_enhancement | W3: =RANDBETWEEN(1,5) -> 2 | X3: =VLOOKUP('Master Sheet'!E3,'Code Options'!$A$1:$R$7,11) -> Rec_Fish | Y3: =RANDBETWEEN(1,5) -> 2 | Z3: =VLOOKUP('Master Sheet'!E3,'Code Options'!$A$1:$R$7,12) -> AR_proj_plan_mngrs
A4: =RANDBETWEEN(1,6) -> 5 | B4: =VLOOKUP('Master Sheet'!A4,'Code Options'!$A$1:$B$7,2) -> Rock | C4: =RANDBETWEEN(1,3) -> 3 | D4: =VLOOKUP('Master Sheet'!C4,'Code Options'!$A$1:$R$7,3) -> Unsure | E4: =RANDBETWEEN(1,5) -> 3 | F4: =VLOOKUP('Master Sheet'!E4,'Code Options'!$A$1:$R$7,4) -> Jon | G4: =RANDBETWEEN(1,3) -> 3 | H4: =VLOOKUP('Master Sheet'!E4,'Code Options'!$A$1:$R$7,5) -> Nick | I4: =RANDBETWEEN(1,4) -> 3 | J4: =VLOOKUP('Master Sheet'!G4,'Code Options'!$A$1:$R$7,6) -> Regional | K4: =RANDBETWEEN(1,4) -> 3 | L4: =VLOOKUP('Master Sheet'!I4,'Code Options'!$A$1:$R$7,7) -> Aggregation | M4: =RANDBETWEEN(1,5) -> 1 | N4: =VLOOKUP('Master Sheet'!K4,'Code Options'!$A$1:$R$7,8) -> Rec.Fish.Mngmt | O4: =RANDBETWEEN(1,5) -> 3 | P4: =VLOOKUP('Master Sheet'!E4,'Code Options'!$A$1:$R$7,9) -> State_Plan | Q4: {=_xlfn.IFS(P4 ="State_Plan", RANDBETWEEN(1,23), P4 ="State_Code", RANDBETWEEN(1,23), P4 = "Fed_Code", 99, P4 = "Summ_Article", 999, P4 = "Guide", 999)} -> 6 | R4: =VLOOKUP(Q4,'States and Locations'!$A$1:$B$26,2) -> New York | S4: =VLOOKUP(Q4,'States and Locations'!$A$1:$D$26,3) -> 42.9667 | T4: =VLOOKUP(Q4,'States and Locations'!$A$1:$D$26,4) -> -75.5167 | U4: =RANDBETWEEN(1,5) -> 4 | V4: =VLOOKUP('Master Sheet'!E4,'Code Options'!$A$1:$R$7,10) -> Mitig. | W4: =RANDBETWEEN(1,5) -> 4 | X4: =VLOOKUP('Master Sheet'!E4,'Code Options'!$A$1:$R$7,11) -> Chart_Fish | Y4: =RANDBETWEEN(1,5) -> 1 | Z4: =VLOOKUP('Master Sheet'!E4,'Code Options'!$A$1:$R$7,12) -> Permit_reg_agencies
A5: =RANDBETWEEN(1,6) -> 1 | B5: =VLOOKUP('Master Sheet'!A5,'Code Options'!$A$1:$B$7,2) -> Composite | C5: =RANDBETWEEN(1,3) -> 1 | D5: =VLOOKUP('Master Sheet'!C5,'Code Options'!$A$1:$R$7,3) -> Retro | E5: =RANDBETWEEN(1,5) -> 5 | F5: =VLOOKUP('Master Sheet'!E5,'Code Options'!$A$1:$R$7,4) -> Nick | G5: =RANDBETWEEN(1,3) -> 1 | H5: =VLOOKUP('Master Sheet'!E5,'Code Options'!$A$1:$R$7,5) -> 0 | I5: =RANDBETWEEN(1,4) -> 3 | J5: =VLOOKUP('Master Sheet'!G5,'Code Options'!$A$1:$R$7,6) -> County/Local | K5: =RANDBETWEEN(1,4) -> 4 | L5: =VLOOKUP('Master Sheet'!I5,'Code Options'!$A$1:$R$7,7) -> Aggregation | M5: =RANDBETWEEN(1,5) -> 1 | N5: =VLOOKUP('Master Sheet'!K5,'Code Options'!$A$1:$R$7,8) -> Creation of AR Mat | O5: =RANDBETWEEN(1,5) -> 4 | P5: =VLOOKUP('Master Sheet'!E5,'Code Options'!$A$1:$R$7,9) -> Guide | Q5: {=_xlfn.IFS(P5 ="State_Plan", RANDBETWEEN(1,23), P5 ="State_Code", RANDBETWEEN(1,23), P5 = "Fed_Code", 99, P5 = "Summ_Article", 999, P5 = "Guide", 999)} -> 999 | R5: =VLOOKUP(Q5,'States and Locations'!$A$1:$B$26,2) -> UNK | S5: =VLOOKUP(Q5,'States and Locations'!$A$1:$D$26,3) -> 25 | T5: =VLOOKUP(Q5,'States and Locations'!$A$1:$D$26,4) -> -90 | U5: =RANDBETWEEN(1,5) -> 3 | V5: =VLOOKUP('Master Sheet'!E5,'Code Options'!$A$1:$R$7,10) -> Wave_attenuation | W5: =RANDBETWEEN(1,5) -> 4 | X5: =VLOOKUP('Master Sheet'!E5,'Code Options'!$A$1:$R$7,11) -> Scuba | Y5: =RANDBETWEEN(1,5) -> 5 | Z5: =VLOOKUP('Master Sheet'!E5,'Code Options'!$A$1:$R$7,12) -> anglers
A6: =RANDBETWEEN(1,6) -> 1 | B6: =VLOOKUP('Master Sheet'!A6,'Code Options'!$A$1:$B$7,2) -> Composite | C6: =RANDBETWEEN(1,3) -> 1 | D6: =VLOOKUP('Master Sheet'!C6,'Code Options'!$A$1:$R$7,3) -> Retro | E6: =RANDBETWEEN(1,5) -> 3 | F6: =VLOOKUP('Master Sheet'!E6,'Code Options'!$A$1:$R$7,4) -> Jon | G6: =RANDBETWEEN(1,3) -> 3 | H6: =VLOOKUP('Master Sheet'!E6,'Code Options'!$A$1:$R$7,5) -> Nick | I6: =RANDBETWEEN(1,4) -> 1 | J6: =VLOOKUP('Master Sheet'!G6,'Code Options'!$A$1:$R$7,6) -> Regional | K6: =RANDBETWEEN(1,4) -> 4 | L6: =VLOOKUP('Master Sheet'!I6,'Code Options'!$A$1:$R$7,7) -> Habitat | M6: =RANDBETWEEN(1,5) -> 5 | N6: =VLOOKUP('Master Sheet'!K6,'Code Options'!$A$1:$R$7,8) -> Creation of AR Mat | O6: =RANDBETWEEN(1,5) -> 1 | P6: =VLOOKUP('Master Sheet'!E6,'Code Options'!$A$1:$R$7,9) -> State_Plan | Q6: {=_xlfn.IFS(P6 ="State_Plan", RANDBETWEEN(1,23), P6 ="State_Code", RANDBETWEEN(1,23), P6 = "Fed_Code", 99, P6 = "Summ_Article", 999, P6 = "Guide", 999)} -> 5 | R6: =VLOOKUP(Q6,'States and Locations'!$A$1:$B$26,2) -> Connecticut | S6: =VLOOKUP(Q6,'States and Locations'!$A$1:$D$26,3) -> 41.6 | T6: =VLOOKUP(Q6,'States and Locations'!$A$1:$D$26,4) -> -72.7 | U6: =RANDBETWEEN(1,5) -> 4 | V6: =VLOOKUP('Master Sheet'!E6,'Code Options'!$A$1:$R$7,10) -> Mitig. | W6: =RANDBETWEEN(1,5) -> 2 | X6: =VLOOKUP('Master Sheet'!E6,'Code Options'!$A$1:$R$7,11) -> Chart_Fish | Y6: =RANDBETWEEN(1,5) -> 5 | Z6: =VLOOKUP('Master Sheet'!E6,'Code Options'!$A$1:$R$7,12) -> Permit_reg_agencies
A7: =RANDBETWEEN(1,6) -> 5 | B7: =VLOOKUP('Master Sheet'!A7,'Code Options'!$A$1:$B$7,2) -> Rock | C7: =RANDBETWEEN(1,3) -> 2 | D7: =VLOOKUP('Master Sheet'!C7,'Code Options'!$A$1:$R$7,3) -> Pro | E7: =RANDBETWEEN(1,5) -> 2 | F7: =VLOOKUP('Master Sheet'!E7,'Code Options'!$A$1:$R$7,4) -> Cyndi | G7: =RANDBETWEEN(1,3) -> 3 | H7: =VLOOKUP('Master Sheet'!E7,'Code Options'!$A$1:$R$7,5) -> Cyndi | I7: =RANDBETWEEN(1,4) -> 2 | J7: =VLOOKUP('Master Sheet'!G7,'Code Options'!$A$1:$R$7,6) -> Regional | K7: =RANDBETWEEN(1,4) -> 2 | L7: =VLOOKUP('Master Sheet'!I7,'Code Options'!$A$1:$R$7,7) -> Production | M7: =RANDBETWEEN(1,5) -> 5 | N7: =VLOOKUP('Master Sheet'!K7,'Code Options'!$A$1:$R$7,8) -> Comm.Fish.Mngmt | O7: =RANDBETWEEN(1,5) -> 5 | P7: =VLOOKUP('Master Sheet'!E7,'Code Options'!$A$1:$R$7,9) -> Fed_Code | Q7: {=_xlfn.IFS(P7 ="State_Plan", RANDBETWEEN(1,23), P7 ="State_Code", RANDBETWEEN(1,23), P7 = "Fed_Code", 99, P7 = "Summ_Article", 999, P7 = "Guide", 999)} -> 99 | R7: =VLOOKUP(Q7,'States and Locations'!$A$1:$B$26,2) -> National | S7: =VLOOKUP(Q7,'States and Locations'!$A$1:$D$26,3) -> 39.8333 | T7: =VLOOKUP(Q7,'States and Locations'!$A$1:$D$26,4) -> -98.5833 | U7: =RANDBETWEEN(1,5) -> 2 | V7: =VLOOKUP('Master Sheet'!E7,'Code Options'!$A$1:$R$7,10) -> Disposal | W7: =RANDBETWEEN(1,5) -> 4 | X7: =VLOOKUP('Master Sheet'!E7,'Code Options'!$A$1:$R$7,11) -> Comm_Fish | Y7: =RANDBETWEEN(1,5) -> 4 | Z7: =VLOOKUP('Master Sheet'!E7,'Code Options'!$A$1:$R$7,12) -> AS_constructors
A8: =RANDBETWEEN(1,6) -> 1 | B8: =VLOOKUP('Master Sheet'!A8,'Code Options'!$A$1:$B$7,2) -> Composite | C8: =RANDBETWEEN(1,3) -> 1 | D8: =VLOOKUP('Master Sheet'!C8,'Code Options'!$A$1:$R$7,3) -> Retro | E8: =RANDBETWEEN(1,5) -> 2 | F8: =VLOOKUP('Master Sheet'!E8,'Code Options'!$A$1:$R$7,4) -> Cyndi | G8: =RANDBETWEEN(1,3) -> 3 | H8: =VLOOKUP('Master Sheet'!E8,'Code Options'!$A$1:$R$7,5) -> Cyndi | I8: =RANDBETWEEN(1,4) -> 4 | J8: =VLOOKUP('Master Sheet'!G8,'Code Options'!$A$1:$R$7,6) -> Regional | K8: =RANDBETWEEN(1,4) -> 1 | L8: =VLOOKUP('Master Sheet'!I8,'Code Options'!$A$1:$R$7,7) -> Biodiversity | M8: =RANDBETWEEN(1,5) -> 4 | N8: =VLOOKUP('Master Sheet'!K8,'Code Options'!$A$1:$R$7,8) -> Fish.Enhancement | O8: =RANDBETWEEN(1,5) -> 1 | P8: =VLOOKUP('Master Sheet'!E8,'Code Options'!$A$1:$R$7,9) -> Fed_Code | Q8: {=_xlfn.IFS(P8 ="State_Plan", RANDBETWEEN(1,23), P8 ="State_Code", RANDBETWEEN(1,23), P8 = "Fed_Code", 99, P8 = "Summ_Article", 999, P8 = "Guide", 999)} -> 99 | R8: =VLOOKUP(Q8,'States and Locations'!$A$1:$B$26,2) -> National | S8: =VLOOKUP(Q8,'States and Locations'!$A$1:$D$26,3) -> 39.8333 | T8: =VLOOKUP(Q8,'States and Locations'!$A$1:$D$26,4) -> -98.5833 | U8: =RANDBETWEEN(1,5) -> 2 | V8: =VLOOKUP('Master Sheet'!E8,'Code Options'!$A$1:$R$7,10) -> Disposal | W8: =RANDBETWEEN(1,5) -> 5 | X8: =VLOOKUP('Master Sheet'!E8,'Code Options'!$A$1:$R$7,11) -> Comm_Fish | Y8: =RANDBETWEEN(1,5) -> 5 | Z8: =VLOOKUP('Master Sheet'!E8,'Code Options'!$A$1:$R$7,12) -> AS_constructors
A9: =RANDBETWEEN(1,6) -> 2 | B9: =VLOOKUP('Master Sheet'!A9,'Code Options'!$A$1:$B$7,2) -> Concrete | C9: =RANDBETWEEN(1,3) -> 3 | D9: =VLOOKUP('Master Sheet'!C9,'Code Options'!$A$1:$R$7,3) -> Unsure | E9: =RANDBETWEEN(1,5) -> 1 | F9: =VLOOKUP('Master Sheet'!E9,'Code Options'!$A$1:$R$7,4) -> Will | G9: =RANDBETWEEN(1,3) -> 3 | H9: =VLOOKUP('Master Sheet'!E9,'Code Options'!$A$1:$R$7,5) -> Will | I9: =RANDBETWEEN(1,4) -> 4 | J9: =VLOOKUP('Master Sheet'!G9,'Code Options'!$A$1:$R$7,6) -> Regional | K9: =RANDBETWEEN(1,4) -> 2 | L9: =VLOOKUP('Master Sheet'!I9,'Code Options'!$A$1:$R$7,7) -> Biodiversity | M9: =RANDBETWEEN(1,5) -> 1 | N9: =VLOOKUP('Master Sheet'!K9,'Code Options'!$A$1:$R$7,8) -> Comm.Fish.Mngmt | O9: =RANDBETWEEN(1,5) -> 1 | P9: =VLOOKUP('Master Sheet'!E9,'Code Options'!$A$1:$R$7,9) -> State_Code | Q9: {=_xlfn.IFS(P9 ="State_Plan", RANDBETWEEN(1,23), P9 ="State_Code", RANDBETWEEN(1,23), P9 = "Fed_Code", 99, P9 = "Summ_Article", 999, P9 = "Guide", 999)} -> 23 | R9: =VLOOKUP(Q9,'States and Locations'!$A$1:$B$26,2) -> Hawaii | S9: =VLOOKUP(Q9,'States and Locations'!$A$1:$D$26,3) -> 20.95 | T9: =VLOOKUP(Q9,'States and Locations'!$A$1:$D$26,4) -> -157.2833 | U9: =RANDBETWEEN(1,5) -> 2 | V9: =VLOOKUP('Master Sheet'!E9,'Code Options'!$A$1:$R$7,10) -> Hab_enhancement | W9: =RANDBETWEEN(1,5) -> 3 | X9: =VLOOKUP('Master Sheet'!E9,'Code Options'!$A$1:$R$7,11) -> Rec_Fish | Y9: =RANDBETWEEN(1,5) -> 4 | Z9: =VLOOKUP('Master Sheet'!E9,'Code Options'!$A$1:$R$7,12) -> AR_proj_plan_mngrs
A10: =RANDBETWEEN(1,6) -> 5 | B10: =VLOOKUP('Master Sheet'!A10,'Code Options'!$A$1:$B$7,2) -> Rock | C10: =RANDBETWEEN(1,3) -> 2 | D10: =VLOOKUP('Master Sheet'!C10,'Code Options'!$A$1:$R$7,3) -> Pro | E10: =RANDBETWEEN(1,5) -> 2 | F10: =VLOOKUP('Master Sheet'!E10,'Code Options'!$A$1:$R$7,4) -> Cyndi | G10: =RANDBETWEEN(1,3) -> 2 | H10: =VLOOKUP('Master Sheet'!E10,'Code Options'!$A$1:$R$7,5) -> Cyndi | I10: =RANDBETWEEN(1,4) -> 3 | J10: =VLOOKUP('Master Sheet'!G10,'Code Options'!$A$1:$R$7,6) -> State | K10: =RANDBETWEEN(1,4) -> 2 | L10: =VLOOKUP('Master Sheet'!I10,'Code Options'!$A$1:$R$7,7) -> Aggregation | M10: =RANDBETWEEN(1,5) -> 2 | N10: =VLOOKUP('Master Sheet'!K10,'Code Options'!$A$1:$R$7,8) -> Comm.Fish.Mngmt | O10: =RANDBETWEEN(1,5) -> 1 | P10: =VLOOKUP('Master Sheet'!E10,'Code Options'!$A$1:$R$7,9) -> Fed_Code | Q10: {=_xlfn.IFS(P10 ="State_Plan", RANDBETWEEN(1,23), P10 ="State_Code", RANDBETWEEN(1,23), P10 = "Fed_Code", 99, P10 = "Summ_Article", 999, P10 = "Guide", 999)} -> 99 | R10: =VLOOKUP(Q10,'States and Locations'!$A$1:$B$26,2) -> National | S10: =VLOOKUP(Q10,'States and Locations'!$A$1:$D$26,3) -> 39.8333 | T10: =VLOOKUP(Q10,'States and Locations'!$A$1:$D$26,4) -> -98.5833 | U10: =RANDBETWEEN(1,5) -> 2 | V10: =VLOOKUP('Master Sheet'!E10,'Code Options'!$A$1:$R$7,10) -> Disposal | W10: =RANDBETWEEN(1,5) -> 1 | X10: =VLOOKUP('Master Sheet'!E10,'Code Options'!$A$1:$R$7,11) -> Comm_Fish | Y10: =RANDBETWEEN(1,5) -> 1 | Z10: =VLOOKUP('Master Sheet'!E10,'Code Options'!$A$1:$R$7,12) -> AS_constructors
A11: =RANDBETWEEN(1,6) -> 2 | B11: =VLOOKUP('Master Sheet'!A11,'Code Options'!$A$1:$B$7,2) -> Concrete | C11: =RANDBETWEEN(1,3) -> 1 | D11: =VLOOKUP('Master Sheet'!C11,'Code Options'!$A$1:$R$7,3) -> Retro | E11: =RANDBETWEEN(1,5) -> 4 | F11: =VLOOKUP('Master Sheet'!E11,'Code Options'!$A$1:$R$7,4) -> LM | G11: =RANDBETWEEN(1,3) -> 3 | H11: =VLOOKUP('Master Sheet'!E11,'Code Options'!$A$1:$R$7,5) -> 0 | I11: =RANDBETWEEN(1,4) -> 1 | J11: =VLOOKUP('Master Sheet'!G11,'Code Options'!$A$1:$R$7,6) -> Regional | K11: =RANDBETWEEN(1,4) -> 4 | L11: =VLOOKUP('Master Sheet'!I11,'Code Options'!$A$1:$R$7,7) -> Habitat | M11: =RANDBETWEEN(1,5) -> 3 | N11: =VLOOKUP('Master Sheet'!K11,'Code Options'!$A$1:$R$7,8) -> Creation of AR Mat | O11: =RANDBETWEEN(1,5) -> 5 | P11: =VLOOKUP('Master Sheet'!E11,'Code Options'!$A$1:$R$7,9) -> Summ_Article | Q11: {=_xlfn.IFS(P11 ="State_Plan", RANDBETWEEN(1,23), P11 ="State_Code", RANDBETWEEN(1,23), P11 = "Fed_Code", 99, P11 = "Summ_Article", 999, P11 = "Guide", 999)} -> 999 | R11: =VLOOKUP(Q11,'States and Locations'!$A$1:$B$26,2) -> UNK | S11: =VLOOKUP(Q11,'States and Locations'!$A$1:$D$26,3) -> 25 | T11: =VLOOKUP(Q11,'States and Locations'!$A$1:$D$26,4) -> -90 | U11: =RANDBETWEEN(1,5) -> 3 | V11: =VLOOKUP('Master Sheet'!E11,'Code Options'!$A$1:$R$7,10) -> Hab_restoration | W11: =RANDBETWEEN(1,5) -> 5 | X11: =VLOOKUP('Master Sheet'!E11,'Code Options'!$A$1:$R$7,11) -> Non-Fish_rec | Y11: =RANDBETWEEN(1,5) -> 2 | Z11: =VLOOKUP('Master Sheet'!E11,'Code Options'!$A$1:$R$7,12) -> people_interested
A12: =RANDBETWEEN(1,6) -> 5 | B12: =VLOOKUP('Master Sheet'!A12,'Code Options'!$A$1:$B$7,2) -> Rock | C12: =RANDBETWEEN(1,3) -> 1 | D12: =VLOOKUP('Master Sheet'!C12,'Code Options'!$A$1:$R$7,3) -> Retro | E12: =RANDBETWEEN(1,5) -> 4 | F12: =VLOOKUP('Master Sheet'!E12,'Code Options'!$A$1:$R$7,4) -> LM | G12: =RANDBETWEEN(1,3) -> 2 | H12: =VLOOKUP('Master Sheet'!E12,'Code Options'!$A$1:$R$7,5) -> 0 | I12: =RANDBETWEEN(1,4) -> 2 | J12: =VLOOKUP('Master Sheet'!G12,'Code Options'!$A$1:$R$7,6) -> State | K12: =RANDBETWEEN(1,4) -> 1 | L12: =VLOOKUP('Master Sheet'!I12,'Code Options'!$A$1:$R$7,7) -> Production | M12: =RANDBETWEEN(1,5) -> 1 | N12: =VLOOKUP('Master Sheet'!K12,'Code Options'!$A$1:$R$7,8) -> Fish.Enhancement | O12: =RANDBETWEEN(1,5) -> 2 | P12: =VLOOKUP('Master Sheet'!E12,'Code Options'!$A$1:$R$7,9) -> Summ_Article | Q12: {=_xlfn.IFS(P12 ="State_Plan", RANDBETWEEN(1,23), P12 ="State_Code", RANDBETWEEN(1,23), P12 = "Fed_Code", 99, P12 = "Summ_Article", 999, P12 = "Guide", 999)} -> 999 | R12: =VLOOKUP(Q12,'States and Locations'!$A$1:$B$26,2) -> UNK | S12: =VLOOKUP(Q12,'States and Locations'!$A$1:$D$26,3) -> 25 | T12: =VLOOKUP(Q12,'States and Locations'!$A$1:$D$26,4) -> -90 | U12: =RANDBETWEEN(1,5) -> 2 | V12: =VLOOKUP('Master Sheet'!E12,'Code Options'!$A$1:$R$7,10) -> Hab_restoration | W12: =RANDBETWEEN(1,5) -> 2 | X12: =VLOOKUP('Master Sheet'!E12,'Code Options'!$A$1:$R$7,11) -> Non-Fish_rec | Y12: =RANDBETWEEN(1,5) -> 3 | Z12: =VLOOKUP('Master Sheet'!E12,'Code Options'!$A$1:$R$7,12) -> people_interested
A13: =RANDBETWEEN(1,6) -> 5 | B13: =VLOOKUP('Master Sheet'!A13,'Code Options'!$A$1:$B$7,2) -> Rock | C13: =RANDBETWEEN(1,3) -> 3 | D13: =VLOOKUP('Master Sheet'!C13,'Code Options'!$A$1:$R$7,3) -> Unsure | E13: =RANDBETWEEN(1,5) -> 3 | F13: =VLOOKUP('Master Sheet'!E13,'Code Options'!$A$1:$R$7,4) -> Jon | G13: =RANDBETWEEN(1,3) -> 1 | H13: =VLOOKUP('Master Sheet'!E13,'Code Options'!$A$1:$R$7,5) -> Nick | I13: =RANDBETWEEN(1,4) -> 1 | J13: =VLOOKUP('Master Sheet'!G13,'Code Options'!$A$1:$R$7,6) -> County/Local | K13: =RANDBETWEEN(1,4) -> 3 | L13: =VLOOKUP('Master Sheet'!I13,'Code Options'!$A$1:$R$7,7) -> Habitat | M13: =RANDBETWEEN(1,5) -> 5 | N13: =VLOOKUP('Master Sheet'!K13,'Code Options'!$A$1:$R$7,8) -> Rec.Fish.Mngmt | O13: =RANDBETWEEN(1,5) -> 2 | P13: =VLOOKUP('Master Sheet'!E13,'Code Options'!$A$1:$R$7,9) -> State_Plan | Q13: {=_xlfn.IFS(P13 ="State_Plan", RANDBETWEEN(1,23), P13 ="State_Code", RANDBETWEEN(1,23), P13 = "Fed_Code", 99, P13 = "Summ_Article", 999, P13 = "Guide", 999)} -> 21 | R13: =VLOOKUP(Q13,'States and Locations'!$A$1:$B$26,2) -> Washington | S13: =VLOOKUP(Q13,'States and Locations'!$A$1:$D$26,3) -> 47.75 | T13: =VLOOKUP(Q13,'States and Locations'!$A$1:$D$26,4) -> -120.7333 | U13: =RANDBETWEEN(1,5) -> 2 | V13: =VLOOKUP('Master Sheet'!E13,'Code Options'!$A$1:$R$7,10) -> Mitig. | W13: =RANDBETWEEN(1,5) -> 4 | X13: =VLOOKUP('Master Sheet'!E13,'Code Options'!$A$1:$R$7,11) -> Chart_Fish | Y13: =RANDBETWEEN(1,5) -> 5 | Z13: =VLOOKUP('Master Sheet'!E13,'Code Options'!$A$1:$R$7,12) -> Permit_reg_agencies
... A251: =RANDBETWEEN(1,6) -> 6 | B251: =VLOOKUP('Master Sheet'!A251,'Code Options'!$A$1:$B$7,2) -> Tires/Rubber | C251: =RANDBETWEEN(1,3) -> 1 | D251: =VLOOKUP('Master Sheet'!C251,'Code Options'!$A$1:$R$7,3) -> Retro | E251: =RANDBETWEEN(1,5) -> 3 | F251: =VLOOKUP('Master Sheet'!E251,'Code Options'!$A$1:$R$7,4) -> Jon | G251: =RANDBETWEEN(1,3) -> 2 | H251: =VLOOKUP('Master Sheet'!E251,'Code Options'!$A$1:$R$7,5) -> Nick | I251: =RANDBETWEEN(1,4) -> 3 | J251: =VLOOKUP('Master Sheet'!G251,'Code Options'!$A$1:$R$7,6) -> State | K251: =RANDBETWEEN(1,4) -> 4 | L251: =VLOOKUP('Master Sheet'!I251,'Code Options'!$A$1:$R$7,7) -> Aggregation | M251: =RANDBETWEEN(1,5) -> 3 | N251: =VLOOKUP('Master Sheet'!K251,'Code Options'!$A$1:$R$7,8) -> Creation of AR Mat | O251: =RANDBETWEEN(1,5) -> 5 | P251: =VLOOKUP('Master Sheet'!E251,'Code Options'!$A$1:$R$7,9) -> State_Plan | Q251: {=_xlfn.IFS(P251 ="State_Plan", RANDBETWEEN(1,23), P251 ="State_Code", RANDBETWEEN(1,23), P251 = "Fed_Code", 99, P251 = "Summ_Article", 999, P251 = "Guide", 999)} -> 5 | R251: =VLOOKUP(Q251,'States and Locations'!$A$1:$B$26,2) -> Connecticut | S251: =VLOOKUP(Q251,'States and Locations'!$A$1:$D$26,3) -> 41.6 | T251: =VLOOKUP(Q251,'States and Locations'!$A$1:$D$26,4) -> -72.7 | U251: =RANDBETWEEN(1,5) -> 2 | V251: =VLOOKUP('Master Sheet'!E251,'Code Options'!$A$1:$R$7,10) -> Mitig. | W251: =RANDBETWEEN(1,5) -> 2 | X251: =VLOOKUP('Master Sheet'!E251,'Code Options'!$A$1:$R$7,11) -> Chart_Fish | Y251: =RANDBETWEEN(1,5) -> 3 | Z251: =VLOOKUP('Master Sheet'!E251,'Code Options'!$A$1:$R$7,12) -> Permit_reg_agencies

Sheet To Be Saved as CSV file
A1: Material_Type | B1: Retro_Proactive | C1: Rev_1 | D1: Rev_2 | E1: Spatial_Scale | F1: Bio_Obj | G1: Concepts_Mentioned | H1: Doc_Type | I1: State_ifapp | J1: State | K1: Lat | L1: Lon | M1: Physical_Obj | N1: Social_Econ_Obj | O1: Target_SH
A2: Rock | B2: Retro | C2: Nick | D2: 0 | E2: State | F2: Biodiversity | G2: Creation of AR Mat | H2: Guide | I2: 999 | J2: UNK | K2: 25 | L2: -90 | M2: Wave_attenuation | N2: Scuba | O2: anglers
A3: Metal | B3: Pro | C3: Will | D3: Will | E3: County/Local | F3: Habitat | G3: Fish.Enhancement | H3: State_Code | I3: 5 | J3: Connecticut | K3: 41.6 | L3: -72.7 | M3: Hab_enhancement | N3: Rec_Fish | O3: AR_proj_plan_mngrs
A4: Other | B4: Pro | C4: Nick | D4: 0 | E4: State | F4: Aggregation | G4: Fish.Enhancement | H4: Guide | I4: 999 | J4: UNK | K4: 25 | L4: -90 | M4: Wave_attenuation | N4: Scuba | O4: anglers
A5: Metal | B5: Pro | C5: LM | D5: 0 | E5: County/Local | F5: Biodiversity | G5: Rec.Fish.Mngmt | H5: Summ_Article | I5: 999 | J5: UNK | K5: 25 | L5: -90 | M5: Hab_restoration | N5: Non-Fish_rec | O5: people_interested
A6: Rock | B6: Unsure | C6: Cyndi | D6: Cyndi | E6: County/Local | F6: Production | G6: Rec.Fish.Mngmt | H6: Fed_Code | I6: 99 | J6: National | K6: 39.8333 | L6: -98.5833 | M6: Disposal | N6: Comm_Fish | O6: AS_constructors
A7: Composite | B7: Retro | C7: Will | D7: Will | E7: State | F7: Habitat | G7: Comm.Fish.Mngmt | H7: State_Code | I7: 12 | J7: South Carolina | K7: 33.8333 | L7: -81.1667 | M7: Hab_enhancement | N7: Rec_Fish | O7: AR_proj_plan_mngrs
A8: Metal | B8: Pro | C8: Will | D8: Will | E8: State | F8: Habitat | G8: Fish.Enhancement | H8: State_Code | I8: 3 | J8: Massachussetts | K8: 42.4 | L8: -71.3833 | M8: Hab_enhancement | N8: Rec_Fish | O8: AR_proj_plan_mngrs
A9: Composite | B9: Pro | C9: Will | D9: Will | E9: Regional | F9: Biodiversity | G9: Comm.Fish.Mngmt | H9: State_Code | I9: 12 | J9: South Carolina | K9: 33.8333 | L9: -81.1667 | M9: Hab_enhancement | N9: Rec_Fish | O9: AR_proj_plan_mngrs
A10: Concrete | B10: Unsure | C10: Will | D10: Will | E10: Regional | F10: Production | G10: Creation of AR Mat | H10: State_Code | I10: 20 | J10: Oregon | K10: 43.9333 | L10: -120.5667 | M10: Hab_enhancement | N10: Rec_Fish | O10: AR_proj_plan_mngrs
A11: Composite | B11: Pro | C11: Nick | D11: 0 | E11: State | F11: Aggregation | G11: Creation of AR Mat | H11: Guide | I11: 999 | J11: UNK | K11: 25 | L11: -90 | M11: Wave_attenuation | N11: Scuba | O11: anglers
A12: Tires/Rubber | B12: Pro | C12: Jon | D12: Nick | E12: State | F12: Aggregation | G12: Fish.Enhancement | H12: State_Plan | I12: 23 | J12: Hawaii | K12: 20.95 | L12: -157.2833 | M12: Mitig. | N12: Chart_Fish | O12: Permit_reg_agencies
A13: Tires/Rubber | B13: Retro | C13: Jon | D13: Nick | E13: Regional | F13: Aggregation | G13: Fish.Enhancement | H13: State_Plan | I13: 9 | J13: Maryland | K13: 39.05 | L13: -76.6333 | M13: Mitig. | N13: Chart_Fish | O13: Permit_reg_agencies
A14: Rock | B14: Pro | C14: Jon | D14: Nick | E14: Regional | F14: Biodiversity | G14: Fish.Enhancement | H14: State_Plan | I14: 21 | J14: Washington | K14: 47.75 | L14: -120.7333 | M14: Mitig. | N14: Chart_Fish | O14: Permit_reg_agencies
A15: Tires/Rubber | B15: Unsure | C15: Will | D15: Will | E15: Regional | F15: Biodiversity | G15: Rec.Fish.Mngmt | H15: State_Code | I15: 7 | J15: New Jersey | K15: 39.8333 | L15: -74.8667 | M15: Hab_enhancement | N15: Rec_Fish | O15: AR_proj_plan_mngrs
A16: Tires/Rubber | B16: Pro | C16: Jon | D16: Nick | E16: Regional | F16: Biodiversity | G16: Creation of AR Mat | H16: State_Plan | I16: 15 | J16: Texas | K16: 31.4667 | L16: -99.3333 | M16: Mitig. | N16: Chart_Fish | O16: Permit_reg_agencies
A17: Tires/Rubber | B17: Retro | C17: Nick | D17: 0 | E17: County/Local | F17: Production | G17: Comm.Fish.Mngmt | H17: Guide | I17: 999 | J17: UNK | K17: 25 | L17: -90 | M17: Wave_attenuation | N17: Scuba | O17: anglers
A18: Metal | B18: Pro | C18: Nick | D18: 0 | E18: State | F18: Production | G18: Rec.Fish.Mngmt | H18: Guide | I18: 999 | J18: UNK | K18: 25 | L18: -90 | M18: Wave_attenuation | N18: Scuba | O18: anglers
A19: Metal | B19: Pro | C19: Will | D19: Will | E19: County/Local | F19: Aggregation | G19: Fish.Enhancement | H19: State_Code | I19: 5 | J19: Connecticut | K19: 41.6 | L19: -72.7 | M19: Hab_enhancement | N19: Rec_Fish | O19: AR_proj_plan_mngrs
A20: Concrete | B20: Pro | C20: Jon | D20: Nick | E20: County/Local | F20: Aggregation | G20: Creation of AR Mat | H20: State_Plan | I20: 18 | J20: Alabama | K20: 32.8333 | L20: -86.6333 | M20: Mitig. | N20: Chart_Fish | O20: Permit_reg_agencies
A21: Tires/Rubber | B21: Pro | C21: Cyndi | D21: Cyndi | E21: Regional | F21: Aggregation | G21: Comm.Fish.Mngmt | H21: Fed_Code | I21: 99 | J21: National | K21: 39.8333 | L21: -98.5833 | M21: Disposal | N21: Comm_Fish | O21: AS_constructors
A22: Rock | B22: Pro | C22: Jon | D22: Nick | E22: Regional | F22: Production | G22: Fish.Enhancement | H22: State_Plan | I22: 22 | J22: Alaska | K22: 64.7333 | L22: -152.4667 | M22: Mitig. | N22: Chart_Fish | O22: Permit_reg_agencies
A23: Rock | B23: Unsure | C23: Will | D23: Will | E23: State | F23: Habitat | G23: Comm.Fish.Mngmt | H23: State_Code | I23: 8 | J23: Delaware | K23: 38.9833 | L23: -75.5167 | M23: Hab_enhancement | N23: Rec_Fish | O23: AR_proj_plan_mngrs
A24: Tires/Rubber | B24: Retro | C24: LM | D24: 0 | E24: Regional | F24: Biodiversity | G24: Fish.Enhancement | H24: Summ_Article | I24: 999 | J24: UNK | K24: 25 | L24: -90 | M24: Hab_restoration | N24: Non-Fish_rec | O24: people_interested
A25: Metal | B25: Pro | C25: Nick | D25: 0 | E25: Regional | F25: Biodiversity | G25: Comm.Fish.Mngmt | H25: Guide | I25: 999 | J25: UNK | K25: 25 | L25: -90 | M25: Wave_attenuation | N25: Scuba | O25: anglers
A26: Concrete | B26: Pro | C26: Nick | D26: 0 | E26: Regional | F26: Production | G26: Creation of AR Mat | H26: Guide | I26: 999 | J26: UNK | K26: 25 | L26: -90 | M26: Wave_attenuation | N26: Scuba | O26: anglers
A27: Tires/Rubber | B27: Retro | C27: Jon | D27: Nick | E27: County/Local | F27: Biodiversity | G27: Fish.Enhancement | H27: State_Plan | I27: 21 | J27: Washington | K27: 47.75 | L27: -120.7333 | M27: Mitig. | N27: Chart_Fish | O27: Permit_reg_agencies
A28: Composite | B28: Unsure | C28: Nick | D28: 0 | E28: County/Local | F28: Aggregation | G28: Creation of AR Mat | H28: Guide | I28: 999 | J28: UNK | K28: 25 | L28: -90 | M28: Wave_attenuation | N28: Scuba | O28: anglers
A29: Other | B29: Pro | C29: Jon | D29: Nick | E29: County/Local | F29: Biodiversity | G29: Fish.Enhancement | H29: State_Plan | I29: 9 | J29: Maryland | K29: 39.05 | L29: -76.6333 | M29: Mitig. | N29: Chart_Fish | O29: Permit_reg_agencies
A30: Other | B30: Unsure | C30: Cyndi | D30: Cyndi | E30: Regional | F30: Production | G30: Creation of AR Mat | H30: Fed_Code | I30: 99 | J30: National | K30: 39.8333 | L30: -98.5833 | M30: Disposal | N30: Comm_Fish | O30: AS_constructors
A31: Metal | B31: Retro | C31: Jon | D31: Nick | E31: State | F31: Biodiversity | G31: Comm.Fish.Mngmt | H31: State_Plan | I31: 13 | J31: Georgia | K31: 32.7167 | L31: -83.5 | M31: Mitig. | N31: Chart_Fish | O31: Permit_reg_agencies
A32: Concrete | B32: Retro | C32: Cyndi | D32: Cyndi | E32: County/Local | F32: Production | G32: Rec.Fish.Mngmt | H32: Fed_Code | I32: 99 | J32: National | K32: 39.8333 | L32: -98.5833 | M32: Disposal | N32: Comm_Fish | O32: AS_constructors
A33: Rock | B33: Retro | C33: Cyndi | D33: Cyndi | E33: Regional | F33: Production | G33: Rec.Fish.Mngmt | H33: Fed_Code | I33: 99 | J33: National | K33: 39.8333 | L33: -98.5833 | M33: Disposal | N33: Comm_Fish | O33: AS_constructors
A34: Concrete | B34: Retro | C34: Will | D34: Will | E34: State | F34: Production | G34: Rec.Fish.Mngmt | H34: State_Code | I34: 9 | J34: Maryland | K34: 39.05 | L34: -76.6333 | M34: Hab_enhancement | N34: Rec_Fish | O34: AR_proj_plan_mngrs
A35: Concrete | B35: Retro | C35: Will | D35: Will | E35: Regional | F35: Production | G35: Creation of AR Mat | H35: State_Code | I35: 10 | J35: Virginia | K35: 37.5167 | L35: -78.6333 | M35: Hab_enhancement | N35: Rec_Fish | O35: AR_proj_plan_mngrs
A36: Other | B36: Retro | C36: Nick | D36: 0 | E36: Regional | F36: Habitat | G36: Creation of AR Mat | H36: Guide | I36: 999 | J36: UNK | K36: 25 | L36: -90 | M36: Wave_attenuation | N36: Scuba | O36: anglers
A37: Concrete | B37: Pro | C37: Cyndi | D37: Cyndi | E37: County/Local | F37: Biodiversity | G37: Fish.Enhancement | H37: Fed_Code | I37: 99 | J37: National | K37: 39.8333 | L37: -98.5833 | M37: Disposal | N37: Comm_Fish | O37: AS_constructors
A38: Metal | B38: Pro | C38: Cyndi | D38: Cyndi | E38: Regional | F38: Production | G38: Rec.Fish.Mngmt | H38: Fed_Code | I38: 99 | J38: National | K38: 39.8333 | L38: -98.5833 | M38: Disposal | N38: Comm_Fish | O38: AS_constructors
A39: Concrete | B39: Retro | C39: Cyndi | D39: Cyndi | E39: Regional | F39: Biodiversity | G39: Comm.Fish.Mngmt | H39: Fed_Code | I39: 99 | J39: National | K39: 39.8333 | L39: -98.5833 | M39: Disposal | N39: Comm_Fish | O39: AS_constructors
A40: Other | B40: Retro | C40: Will | D40: Will | E40: State | F40: Habitat | G40: Rec.Fish.Mngmt | H40: State_Code | I40: 13 | J40: Georgia | K40: 32.7167 | L40: -83.5 | M40: Hab_enhancement | N40: Rec_Fish | O40: AR_proj_plan_mngrs
...
